Workbook
Name CLASE: Listas!#REF!
Name EQUIPO: Listas!#REF!
Name SECCION: Listas!$C$3:$C$12
Name TIPO1: Listas!$A$3:$A$5
Name TIPO2: Listas!$B$8:$B$203

Sheet Instructivo
A2: #VALUE! | D2: INDICADOR DE PARADAS CPO EL PAJUIL Instructivo de la herramienta | R2: Código:
R3: Versión:
R4: Fecha de Aprobación:
A6: 1. Identificar clase y tipo de parada.
A7: A continuación se presenta el árbol para identificación y registro de las paradas de planta:
A10: Tipo I | E10: Tipo II | I10: Sección | M10: Equipo | Q10: Causa de falla / Observación
A17: �
A26: �
A46: 2. Cómo registrar las paradas.
A48: Resgistro fecha y tiempos
A50: 1. Registrar fecha
A51: 2. Automáticamente se registrará el año correspondiente. No digitar ningún valor.
A52: 3. Automáticamente se registrará el mes correspondiente. No digitar ningún valor.
A53: 4. Registrar hora de inicio de la parada
A54: 5. Registrar hora de fin de la parada
A55: 6. En la columna Duración, se calculará automáticamente el tiempo de parada. No digitar ningún valor.
A57: Si es parada programada
A59: 7. Seleccionar en columna Tipo I: Programada
... A91: 12. Fin.

Sheet Resumen mensual y Gráficas
C5: 41852 | D5: 41883 | E5: 41913 | F5: 41944 | G5: 41974 | H5: 42005 | I5: 42036 | J5: 42064 | K5: 42095 | L5: 42125 | M5: 42156 | N5: 42186 | O5: 42217 | P5: 42248 | Q5: 42278 | R5: 42309 | S5: 42339 | T5: ene | U5: feb | V5: mar | W5: abr | X5: may | Y5: junio | Z5: julio
B6: Horas programadas de proceso | C6: =SUMIF(#REF!,8,#REF!) -> #REF! | D6: =SUMIF(#REF!,9,#REF!) -> #REF! | E6: =SUMIF(#REF!,10,#REF!) -> #REF! | F6: =SUMIF(#REF!,11,#REF!) -> #REF! | G6: =SUMIF(#REF!,12,#REF!) -> #REF! | H6: =SUMIF(#REF!,1,#REF!) -> #REF! | I6: =SUMIF(#REF!,2,#REF!) -> #REF! | J6: =SUMIF(#REF!,3,#REF!) -> #REF! | K6: =SUMIF(#REF!,4,#REF!) -> #REF! | L6: =SUMIF(#REF!,5,#REF!) -> #REF! | M6: =SUMIF(#REF!,6,#REF!) -> #REF! | N6: =SUMIF(#REF!,7,#REF!) -> #REF! | O6: =SUMIF(#REF!,8,#REF!) -> #REF! | P6: =SUMIF(#REF!,9,#REF!) -> #REF! | Q6: =SUMIF(#REF!,10,#REF!) -> #REF! | R6: =SUMIF(#REF!,11,#REF!) -> #REF! | S6: =SUMIF(#REF!,12,#REF!) -> #REF! | T6: =SUMIF(#REF!,1,#REF!) -> #REF! | U6: =SUMIF(#REF!,2,#REF!) -> #REF! | V6: =SUMIF(#REF!,3,#REF!) -> #REF! | W6: =SUMIF(#REF!,4,#REF!) -> #REF! | X6: =SUMIF(#REF!,5,#REF!) -> #REF! | Y6: =SUMIF(#REF!,6,#REF!) -> #REF! | Z6: =SUMIF(#REF!,7,#REF!) -> #REF!
B7: %Paradas externas | G7: 0.0817 | H7: =SUMIF(#REF!,1,#REF!)/H6 -> #REF! | I7: =SUMIF(#REF!,2,#REF!)/I6 -> #REF! | J7: =SUMIF(#REF!,3,#REF!)/J6 -> #REF! | K7: =SUMIF(#REF!,4,#REF!)/K6 -> #REF! | L7: =SUMIF(#REF!,5,#REF!)/L6 -> #REF! | M7: =SUMIF(#REF!,6,#REF!)/M6 -> #REF! | N7: =SUMIF(#REF!,7,#REF!)/N6 -> #REF! | O7: =SUMIF(#REF!,8,#REF!)/O6 -> #REF! | P7: =SUMIF(#REF!,9,#REF!)/P6 -> #REF! | Q7: =SUMIF(#REF!,10,#REF!)/Q6 -> #REF! | R7: =SUMIF(#REF!,11,#REF!)/R6 -> #REF! | S7: =SUMIF(#REF!,12,#REF!)/S6 -> #REF! | T7: =SUMIF(#REF!,1,#REF!)/T6 -> #REF! | U7: =SUMIF(#REF!,2,#REF!)/U6 -> #REF! | V7: =SUMIF(#REF!,3,#REF!)/V6 -> #REF! | W7: =SUMIF(#REF!,4,#REF!)/W6 -> #REF! | X7: =SUMIF(#REF!,5,#REF!)/X6 -> #REF! | Y7: =SUMIF(#REF!,6,#REF!)/Y6 -> #REF! | Z7: =SUMIF(#REF!,7,#REF!)/Z6 -> #REF!
B8: %Paradas por mantenimiento | G8: 0.1648 | I8: =SUMIF(#REF!,2,#REF!)/I6 -> #REF! | J8: =SUMIF(#REF!,3,#REF!)/J6 -> #REF! | K8: =SUMIF(#REF!,4,#REF!)/K6 -> #REF! | L8: =SUMIF(#REF!,5,#REF!)/L6 -> #REF! | M8: =SUMIF(#REF!,6,#REF!)/M6 -> #REF! | N8: =SUMIF(#REF!,7,#REF!)/N6 -> #REF! | O8: =SUMIF(#REF!,8,#REF!)/O6 -> #REF! | P8: =SUMIF(#REF!,9,#REF!)/P6 -> #REF! | Q8: =SUMIF(#REF!,10,#REF!)/Q6 -> #REF! | R8: =SUMIF(#REF!,11,#REF!)/R6 -> #REF! | S8: =SUMIF(#REF!,12,#REF!)/S6 -> #REF! | T8: =SUMIF(#REF!,1,#REF!)/T6 -> #REF! | U8: =SUMIF(#REF!,2,#REF!)/U6 -> #REF! | V8: =SUMIF(#REF!,3,#REF!)/V6 -> #REF! | W8: =SUMIF(#REF!,4,#REF!)/W6 -> #REF! | X8: =SUMIF(#REF!,5,#REF!)/X6 -> #REF! | Y8: =SUMIF(#REF!,6,#REF!)/Y6 -> #REF! | Z8: =SUMIF(#REF!,7,#REF!)/Z6 -> #REF!
B9: %Paradas Operativas | G9: 0.0047 | H9: =SUMIF(#REF!,1,#REF!)/H6 -> #REF! | I9: =SUMIF(#REF!,2,#REF!)/I6 -> #REF! | J9: =SUMIF(#REF!,3,#REF!)/J6 -> #REF! | K9: =SUMIF(#REF!,4,#REF!)/K6 -> #REF! | L9: =SUMIF(#REF!,5,#REF!)/L6 -> #REF! | M9: =SUMIF(#REF!,6,#REF!)/M6 -> #REF! | N9: =SUMIF(#REF!,7,#REF!)/N6 -> #REF! | O9: =SUMIF(#REF!,8,#REF!)/O6 -> #REF! | P9: =SUMIF(#REF!,8,#REF!)/P6 -> #REF! | Q9: =SUMIF(#REF!,10,#REF!)/Q6 -> #REF! | R9: =SUMIF(#REF!,11,#REF!)/R6 -> #REF! | S9: =SUMIF(#REF!,12,#REF!)/S6 -> #REF! | T9: =SUMIF(#REF!,1,#REF!)/T6 -> #REF! | U9: =SUMIF(#REF!,2,#REF!)/U6 -> #REF! | V9: =SUMIF(#REF!,3,#REF!)/V6 -> #REF! | W9: =SUMIF(#REF!,4,#REF!)/W6 -> #REF! | X9: =SUMIF(#REF!,5,#REF!)/X6 -> #REF! | Y9: =SUMIF(#REF!,6,#REF!)/Y6 -> #REF! | Z9: =SUMIF(#REF!,7,#REF!)/Z6 -> #REF!
B10: %Paradas mtto y operativas | G10: =SUM(G8:G9) -> 0.1695 | H10: =SUM(H8:H9) -> #REF! | I10: =SUM(I8:I9) -> #REF! | J10: =SUM(J8:J9) -> #REF! | K10: =SUM(K8:K9) -> #REF! | L10: =SUM(L8:L9) -> #REF! | M10: =SUM(M8:M9) -> #REF! | N10: =SUM(N8:N9) -> #REF! | ... Z10: =SUM(Z8:Z9) -> #REF!
B11: %Paradas total | C11: 0.21048639 | D11: 0.25246852 | E11: 0.30632438 | F11: 0.28676731 | G11: =SUM(G7:G9) -> 0.2512 | H11: =SUM(H7:H9) -> #REF! | I11: =SUM(I7:I9) -> #REF! | J11: =SUM(J7:J9) -> #REF! | K11: =SUM(K7:K9) -> #REF! | L11: =SUM(L7:L9) -> #REF! | M11: =SUM(M7:M9) -> #REF! | N11: =SUM(N7:N9) -> #REF! | ... Z11: =SUM(Z7:Z9) -> #REF!
B12: Meta paradas mtto y operativas | C12: 0.1 | D12: 0.1 | E12: 0.1 | F12: 0.1 | G12: 0.1 | H12: 0.1 | I12: 0.1 | J12: 0.1 | K12: 0.1 | L12: 0.1 | M12: 0.1 | N12: 0.1 | O12: 0.1 | P12: 0.1 | Q12: 0.1 | R12: 0.1 | S12: 0.1 | T12: 0.1 | U12: 0.1 | V12: 0.1 | W12: 0.1 | X12: 0.1 | Y12: 0.1 | Z12: 0.1
O29: =100+N29 -> 100
B38: AÑO | C38: 2016
B39: CLASE | C39: No programada
B40: TIPO I | C40: Por mantenimiento
B42: Suma de DURACIÓN (h) | C42: Etiquetas de columna
B43: Etiquetas de fila | C43: 7 | D43: Total general
B44: Caldera VR 16 | C44: 8.0833333 | D44: 8.0833333 | E44: =+GETPIVOTDATA("DURACIÓN (h)",$C$44,"EQUIPO","Desfrutador")/SUM($D$44:$D$58) -> #REF!
B45: Autoclave N°1 | C45: 4.0833333 | D45: 4.0833333
B46: Redler a tolva de pesaje | C46: 3.8833333 | D46: 3.8833333
B47: Esclusa de fibras | C47: 1.4166667 | D47: 1.4166667
B48: Transportador sinfín fibras alimentacion a caldera | C48: 1.3833333 | D48: 1.3833333
B49: Tamiz DE CRUDO 1 | C49: 0.7 | D49: 0.7
B50: Bomba lodos preclarificador | C50: 0.61666667 | D50: 0.61666667
B51: Redler de fruta esterelizada N°1 | C51: 0.53333333 | D51: 0.53333333
B52: Bomba lodos a Florentinos | C52: 0.5 | D52: 0.5
B53: Indexer N° 1 | C53: 0.43333333 | D53: 0.43333333
B54: Transportador sinfín retorno de fruta | C54: 0.41666667 | D54: 0.41666667
B55: Redler de fruta esterelizada N°2 | C55: 0.075 | D55: 0.075
B56: Total general | C56: 22.125 | D56: 22.125

Sheet Registrio Paros
L2: Código:
L3: Versión:
L4: Fecha de Aprobación:
A6: Fecha | B6: Día | C6: Mes | D6: Hora inicio | E6: Hora fin | F6: Tiempo paro (horas) | G6: Tipo I | H6: Tipo II | I6: Sección | J6: Equipo | K6: Causa de falla / Observación | L6: Responsable diligenciamiento
A7: 45937 | B7: =IF(Tabla13[[#This Row],[Fecha]]="","",TEXT(Tabla13[[#This Row],[Fecha]],"aaaa")) -> martes | C7: =IF(Tabla13[[#This Row],[Fecha]]="","",TEXT(Tabla13[[#This Row],[Fecha]],"mmmm")) -> octubre | D7: 0.35555556 | E7: 0.49861111 | F7: =HOUR(Tabla13[[#This Row],[Hora fin ]]-Tabla13[[#This Row],[Hora inicio]])+MINUTE(Tabla13[[#This Row],[Hora fin ]]-Tabla13[[#This Row],[Hora inicio]])/60 -> 3.4333333 | G7: Operativa | H7: Atascamiento | I7: Extracción | J7: Prensa de doble tornillo | K7: ATASCAMIENTO EN LA PRENSA P15
A8: 45937 | B8: =IF(Tabla13[[#This Row],[Fecha]]="","",TEXT(Tabla13[[#This Row],[Fecha]],"aaaa")) -> martes | C8: =IF(Tabla13[[#This Row],[Fecha]]="","",TEXT(Tabla13[[#This Row],[Fecha]],"mmmm")) -> octubre | D8: 0.57708333 | E8: 0.58055556 | F8: =HOUR(Tabla13[[#This Row],[Hora fin ]]-Tabla13[[#This Row],[Hora inicio]])+MINUTE(Tabla13[[#This Row],[Hora fin ]]-Tabla13[[#This Row],[Hora inicio]])/60 -> 0.083333333 | G8: Programada | H8: Arranque planta | I8: Generacion electrica | J8: Planta eléctrica de 1250 Kva | K8: CAMBIO DE ENERGIA
A9: 45937 | B9: =IF(Tabla13[[#This Row],[Fecha]]="","",TEXT(Tabla13[[#This Row],[Fecha]],"aaaa")) -> martes | C9: =IF(Tabla13[[#This Row],[Fecha]]="","",TEXT(Tabla13[[#This Row],[Fecha]],"mmmm")) -> octubre | D9: 0.96875 | E9: 0.97986111 | F9: =HOUR(Tabla13[[#This Row],[Hora fin ]]-Tabla13[[#This Row],[Hora inicio]])+MINUTE(Tabla13[[#This Row],[Hora fin ]]-Tabla13[[#This Row],[Hora inicio]])/60 -> 0.26666667 | G9: Operativa | H9: Atascamiento | I9: Extracción | J9: Prensa de doble tornillo | K9: ATASCAMIENTO EN LA PRENSA P15
A10: 45938 | B10: =IF(Tabla13[[#This Row],[Fecha]]="","",TEXT(Tabla13[[#This Row],[Fecha]],"aaaa")) -> miércoles | C10: =IF(Tabla13[[#This Row],[Fecha]]="","",TEXT(Tabla13[[#This Row],[Fecha]],"mmmm")) -> octubre | D10: 0.57361111 | E10: 0.57708333 | F10: =HOUR(Tabla13[[#This Row],[Hora fin ]]-Tabla13[[#This Row],[Hora inicio]])+MINUTE(Tabla13[[#This Row],[Hora fin ]]-Tabla13[[#This Row],[Hora inicio]])/60 -> 0.083333333 | G10: Programada | H10: Arranque planta | I10: Generacion electrica | J10: Planta eléctrica de 1250 Kva | K10: CAMBIO DE ENERGIA
A11: 45938 | B11: =IF(Tabla13[[#This Row],[Fecha]]="","",TEXT(Tabla13[[#This Row],[Fecha]],"aaaa")) -> miércoles | C11: =IF(Tabla13[[#This Row],[Fecha]]="","",TEXT(Tabla13[[#This Row],[Fecha]],"mmmm")) -> octubre | D11: 0.72638889 | E11: 0.73611111 | F11: =HOUR(Tabla13[[#This Row],[Hora fin ]]-Tabla13[[#This Row],[Hora inicio]])+MINUTE(Tabla13[[#This Row],[Hora fin ]]-Tabla13[[#This Row],[Hora inicio]])/60 -> 0.23333333 | G11: Operativa | H11: Falta de fruta esterilizada | I11: Esterilización | J11: Esterilizador Oblicuo Automático | K11: FALTA DE FRUTO ESTERILIZADO
A12: 45939 | B12: =IF(Tabla13[[#This Row],[Fecha]]="","",TEXT(Tabla13[[#This Row],[Fecha]],"aaaa")) -> jueves | C12: =IF(Tabla13[[#This Row],[Fecha]]="","",TEXT(Tabla13[[#This Row],[Fecha]],"mmmm")) -> octubre | D12: 0.60347222 | E12: 0.61458333 | F12: =HOUR(Tabla13[[#This Row],[Hora fin ]]-Tabla13[[#This Row],[Hora inicio]])+MINUTE(Tabla13[[#This Row],[Hora fin ]]-Tabla13[[#This Row],[Hora inicio]])/60 -> 0.26666667 | G12: Mantenimiento | H12: Falla mecánica | I12: Desfibrado | J12: Redler #3 para Combustible | K12: FALLA EN EL REDLER
A13: 45939 | B13: =IF(Tabla13[[#This Row],[Fecha]]="","",TEXT(Tabla13[[#This Row],[Fecha]],"aaaa")) -> jueves | C13: =IF(Tabla13[[#This Row],[Fecha]]="","",TEXT(Tabla13[[#This Row],[Fecha]],"mmmm")) -> octubre | D13: 0.64305556 | E13: 0.64791667 | F13: =HOUR(Tabla13[[#This Row],[Hora fin ]]-Tabla13[[#This Row],[Hora inicio]])+MINUTE(Tabla13[[#This Row],[Hora fin ]]-Tabla13[[#This Row],[Hora inicio]])/60 -> 0.11666667 | G13: Mantenimiento | H13: Falla mecánica | I13: Raquis | J13: Banda #1 para Racimos Vacíos | K13: FALLA EN BANDA DE RAQUIS
A14: 45939 | B14: =IF(Tabla13[[#This Row],[Fecha]]="","",TEXT(Tabla13[[#This Row],[Fecha]],"aaaa")) -> jueves | C14: =IF(Tabla13[[#This Row],[Fecha]]="","",TEXT(Tabla13[[#This Row],[Fecha]],"mmmm")) -> octubre | D14: 0.67916667 | E14: 0.68402778 | F14: =HOUR(Tabla13[[#This Row],[Hora fin ]]-Tabla13[[#This Row],[Hora inicio]])+MINUTE(Tabla13[[#This Row],[Hora fin ]]-Tabla13[[#This Row],[Hora inicio]])/60 -> 0.11666667 | G14: Programada | H14: Arranque planta | I14: Generacion electrica | J14: Planta eléctrica de 72 Kva | K14: CAMBIO DE ENERGIA
A15: 45940 | B15: =IF(Tabla13[[#This Row],[Fecha]]="","",TEXT(Tabla13[[#This Row],[Fecha]],"aaaa")) -> viernes | C15: =IF(Tabla13[[#This Row],[Fecha]]="","",TEXT(Tabla13[[#This Row],[Fecha]],"mmmm")) -> octubre | D15: 0.38472222 | E15: 0.39583333 | F15: =HOUR(Tabla13[[#This Row],[Hora fin ]]-Tabla13[[#This Row],[Hora inicio]])+MINUTE(Tabla13[[#This Row],[Hora fin ]]-Tabla13[[#This Row],[Hora inicio]])/60 -> 0.26666667 | G15: Operativa | H15: Falta de fruta esterilizada | I15: Esterilización | J15: Esterilizador Oblicuo Automático | K15: FALTA DE FRUTO ESTERILIZADO
A16: 45940 | B16: =IF(Tabla13[[#This Row],[Fecha]]="","",TEXT(Tabla13[[#This Row],[Fecha]],"aaaa")) -> viernes | C16: =IF(Tabla13[[#This Row],[Fecha]]="","",TEXT(Tabla13[[#This Row],[Fecha]],"mmmm")) -> octubre | D16: 0.48472222 | E16: 0.48819444 | F16: =HOUR(Tabla13[[#This Row],[Hora fin ]]-Tabla13[[#This Row],[Hora inicio]])+MINUTE(Tabla13[[#This Row],[Hora fin ]]-Tabla13[[#This Row],[Hora inicio]])/60 -> 0.083333333 | G16: Programada | H16: Arranque planta | I16: Generacion electrica | J16: Planta eléctrica de 1250 Kva | K16: CAMBIO DE ENERGIA
A17: 45940 | B17: =IF(Tabla13[[#This Row],[Fecha]]="","",TEXT(Tabla13[[#This Row],[Fecha]],"aaaa")) -> viernes | C17: =IF(Tabla13[[#This Row],[Fecha]]="","",TEXT(Tabla13[[#This Row],[Fecha]],"mmmm")) -> octubre | D17: 0.86111111 | E17: 0.87291667 | F17: =HOUR(Tabla13[[#This Row],[Hora fin ]]-Tabla13[[#This Row],[Hora inicio]])+MINUTE(Tabla13[[#This Row],[Hora fin ]]-Tabla13[[#This Row],[Hora inicio]])/60 -> 0.28333333 | G17: Operativa | H17: Falta de fruta esterilizada | I17: Esterilización | J17: Esterilizador Oblicuo Automático | K17: FALTA DE FRUTO ESTERILIZADO
A18: 45941 | B18: =IF(Tabla13[[#This Row],[Fecha]]="","",TEXT(Tabla13[[#This Row],[Fecha]],"aaaa")) -> sábado | C18: =IF(Tabla13[[#This Row],[Fecha]]="","",TEXT(Tabla13[[#This Row],[Fecha]],"mmmm")) -> octubre | D18: 0.015972222 | E18: 0.041666667 | F18: =HOUR(Tabla13[[#This Row],[Hora fin ]]-Tabla13[[#This Row],[Hora inicio]])+MINUTE(Tabla13[[#This Row],[Hora fin ]]-Tabla13[[#This Row],[Hora inicio]])/60 -> 0.61666667 | G18: Operativa | H18: Falta de fruta esterilizada | I18: Esterilización | J18: Esterilizador Oblicuo Automático | K18: FALTA DE FRUTO ESTERILIZADO
... A69: 45971 | B69: =IF(Tabla13[[#This Row],[Fecha]]="","",TEXT(Tabla13[[#This Row],[Fecha]],"aaaa")) -> lunes | C69: =IF(Tabla13[[#This Row],[Fecha]]="","",TEXT(Tabla13[[#This Row],[Fecha]],"mmmm")) -> noviembre | D69: 0.66111111 | E69: 0.66319444 | F69: =HOUR(Tabla13[[#This Row],[Hora fin ]]-Tabla13[[#This Row],[Hora inicio]])+MINUTE(Tabla13[[#This Row],[Hora fin ]]-Tabla13[[#This Row],[Hora inicio]])/60 -> 0.05 | G69: Programada | H69: Arranque planta | I69: Generacion electrica | J69: Planta eléctrica de 1250 Kva | K69: CAMBIO DE ENERGIA
A70: 45971 | B70: =IF(Tabla13[[#This Row],[Fecha]]="","",TEXT(Tabla13[[#This Row],[Fecha]],"aaaa")) -> lunes | C70: =IF(Tabla13[[#This Row],[Fecha]]="","",TEXT(Tabla13[[#This Row],[Fecha]],"mmmm")) -> noviembre | D70: 0.7375 | E70: 0.76111111 | F70: =HOUR(Tabla13[[#This Row],[Hora fin ]]-Tabla13[[#This Row],[Hora inicio]])+MINUTE(Tabla13[[#This Row],[Hora fin ]]-Tabla13[[#This Row],[Hora inicio]])/60 -> 0.56666667 | G70: Operativa | H70: Atascamiento | I70: Extracción | J70: Digestor Vertical | K70: ATASCAMIENTO DUCTO DEL DIGESTOR | CA70: ,
A71: 45975 | B71: =IF(Tabla13[[#This Row],[Fecha]]="","",TEXT(Tabla13[[#This Row],[Fecha]],"aaaa")) -> viernes | C71: =IF(Tabla13[[#This Row],[Fecha]]="","",TEXT(Tabla13[[#This Row],[Fecha]],"mmmm")) -> noviembre | D71: 0.57569444 | E71: 0.57847222 | F71: =HOUR(Tabla13[[#This Row],[Hora fin ]]-Tabla13[[#This Row],[Hora inicio]])+MINUTE(Tabla13[[#This Row],[Hora fin ]]-Tabla13[[#This Row],[Hora inicio]])/60 -> 0.066666667 | G71: Programada | H71: Arranque planta | I71: Generacion electrica | J71: Planta eléctrica de 1250 Kva | K71: CAMBIO DE ENERGIA
A72: 45976 | B72: =IF(Tabla13[[#This Row],[Fecha]]="","",TEXT(Tabla13[[#This Row],[Fecha]],"aaaa")) -> sábado | C72: =IF(Tabla13[[#This Row],[Fecha]]="","",TEXT(Tabla13[[#This Row],[Fecha]],"mmmm")) -> noviembre | D72: 0.47916667 | E72: 0.58194444 | F72: =HOUR(Tabla13[[#This Row],[Hora fin ]]-Tabla13[[#This Row],[Hora inicio]])+MINUTE(Tabla13[[#This Row],[Hora fin ]]-Tabla13[[#This Row],[Hora inicio]])/60 -> 2.4666667 | G72: Operativa | H72: Falla mecánica | I72: Desfrutado | J72: Sinfín para Fruto Suelto | K72: FALLA EN SINFÍN BAJO DESFRUTADOR
A73: 45977 | B73: =IF(Tabla13[[#This Row],[Fecha]]="","",TEXT(Tabla13[[#This Row],[Fecha]],"aaaa")) -> domingo | C73: =IF(Tabla13[[#This Row],[Fecha]]="","",TEXT(Tabla13[[#This Row],[Fecha]],"mmmm")) -> noviembre | D73: 0.58055556 | E73: 0.61041667 | F73: =HOUR(Tabla13[[#This Row],[Hora fin ]]-Tabla13[[#This Row],[Hora inicio]])+MINUTE(Tabla13[[#This Row],[Hora fin ]]-Tabla13[[#This Row],[Hora inicio]])/60 -> 0.71666667 | G73: Operativa | H73: Falta de fruta esterilizada | I73: Esterilización | J73: Esterilizador Oblicuo Automático | K73: FALTA DE FRUTO ESTERILIZADO
A74: 45977 | B74: =IF(Tabla13[[#This Row],[Fecha]]="","",TEXT(Tabla13[[#This Row],[Fecha]],"aaaa")) -> domingo | C74: =IF(Tabla13[[#This Row],[Fecha]]="","",TEXT(Tabla13[[#This Row],[Fecha]],"mmmm")) -> noviembre | D74: 0.77569444 | E74: 0.79652778 | F74: =HOUR(Tabla13[[#This Row],[Hora fin ]]-Tabla13[[#This Row],[Hora inicio]])+MINUTE(Tabla13[[#This Row],[Hora fin ]]-Tabla13[[#This Row],[Hora inicio]])/60 -> 0.5 | G74: Operativa | H74: Falla mecánica | I74: Esterilización | J74: Redler de Fruto Esterilizado | K74: FALLA EN EL REDLER DE FRUTO ESTERILIZADO
A75: 45979 | B75: =IF(Tabla13[[#This Row],[Fecha]]="","",TEXT(Tabla13[[#This Row],[Fecha]],"aaaa")) -> martes | C75: =IF(Tabla13[[#This Row],[Fecha]]="","",TEXT(Tabla13[[#This Row],[Fecha]],"mmmm")) -> noviembre | D75: 0.49375 | E75: 0.49583333 | F75: =HOUR(Tabla13[[#This Row],[Hora fin ]]-Tabla13[[#This Row],[Hora inicio]])+MINUTE(Tabla13[[#This Row],[Hora fin ]]-Tabla13[[#This Row],[Hora inicio]])/60 -> 0.05 | G75: Programada | H75: Arranque planta | I75: Generacion electrica | J75: Planta eléctrica de 1250 Kva | K75: CAMBIO DE ENERGIA
A76: 45979 | B76: =IF(Tabla13[[#This Row],[Fecha]]="","",TEXT(Tabla13[[#This Row],[Fecha]],"aaaa")) -> martes | C76: =IF(Tabla13[[#This Row],[Fecha]]="","",TEXT(Tabla13[[#This Row],[Fecha]],"mmmm")) -> noviembre | D76: 0.50555556 | E76: 0.89583333 | F76: =HOUR(Tabla13[[#This Row],[Hora fin ]]-Tabla13[[#This Row],[Hora inicio]])+MINUTE(Tabla13[[#This Row],[Hora fin ]]-Tabla13[[#This Row],[Hora inicio]])/60 -> 9.3666667 | G76: Mantenimiento | H76: Falla mecánica | I76: Generación de vapor | J76: Caldera sinfín alimentador | K76: FALLA EN SINFÍN ALIMENTADOR DE CALDERA
A77: 45979 | B77: =IF(Tabla13[[#This Row],[Fecha]]="","",TEXT(Tabla13[[#This Row],[Fecha]],"aaaa")) -> martes | C77: =IF(Tabla13[[#This Row],[Fecha]]="","",TEXT(Tabla13[[#This Row],[Fecha]],"mmmm")) -> noviembre | D77: 0.95833333 | E77: 0.99027778 | F77: =HOUR(Tabla13[[#This Row],[Hora fin ]]-Tabla13[[#This Row],[Hora inicio]])+MINUTE(Tabla13[[#This Row],[Hora fin ]]-Tabla13[[#This Row],[Hora inicio]])/60 -> 0.76666667 | G77: Operativa | H77: Falla operativa | I77: Extracción | J77: Prensa de doble tornillo | K77: QUEDA EN VACIO EL PANTALON DE LA PRENSA P15
A78: 45980 | B78: =IF(Tabla13[[#This Row],[Fecha]]="","",TEXT(Tabla13[[#This Row],[Fecha]],"aaaa")) -> miércoles | C78: =IF(Tabla13[[#This Row],[Fecha]]="","",TEXT(Tabla13[[#This Row],[Fecha]],"mmmm")) -> noviembre | D78: 0.069444444 | E78: 0.075694444 | F78: =HOUR(Tabla13[[#This Row],[Hora fin ]]-Tabla13[[#This Row],[Hora inicio]])+MINUTE(Tabla13[[#This Row],[Hora fin ]]-Tabla13[[#This Row],[Hora inicio]])/60 -> 0.15 | G78: Programada | H78: Arranque planta | I78: Generacion electrica | J78: Planta eléctrica de 1250 Kva | K78: CAMBIO DE ENERGIA
A79: 45981 | B79: =IF(Tabla13[[#This Row],[Fecha]]="","",TEXT(Tabla13[[#This Row],[Fecha]],"aaaa")) -> jueves | C79: =IF(Tabla13[[#This Row],[Fecha]]="","",TEXT(Tabla13[[#This Row],[Fecha]],"mmmm")) -> noviembre | D79: 0.83333333 | E79: 1 | F79: =HOUR(Tabla13[[#This Row],[Hora fin ]]-Tabla13[[#This Row],[Hora inicio]])+MINUTE(Tabla13[[#This Row],[Hora fin ]]-Tabla13[[#This Row],[Hora inicio]])/60 -> 4 | G79: Operativa | H79: Falla mecánica | I79: Extracción | J79: Elevador de Fruto | K79: SE REVENTO CADENA DEL ELEVADOR DE FRUTO
A80: 45982 | B80: =IF(Tabla13[[#This Row],[Fecha]]="","",TEXT(Tabla13[[#This Row],[Fecha]],"aaaa")) -> viernes | C80: =IF(Tabla13[[#This Row],[Fecha]]="","",TEXT(Tabla13[[#This Row],[Fecha]],"mmmm")) -> noviembre | D80: 0.00069444444 | E80: 0.43055556 | F80: =HOUR(Tabla13[[#This Row],[Hora fin ]]-Tabla13[[#This Row],[Hora inicio]])+MINUTE(Tabla13[[#This Row],[Hora fin ]]-Tabla13[[#This Row],[Hora inicio]])/60 -> 10.316667 | G80: Operativa | H80: Falla mecánica | I80: Extracción | J80: Elevador de Fruto | K80: SE REVENTO CADENA DEL ELEVADOR DE FRUTO
A81: 45982 | B81: =IF(Tabla13[[#This Row],[Fecha]]="","",TEXT(Tabla13[[#This Row],[Fecha]],"aaaa")) -> viernes | C81: =IF(Tabla13[[#This Row],[Fecha]]="","",TEXT(Tabla13[[#This Row],[Fecha]],"mmmm")) -> noviembre | D81: 0.52083333 | E81: 0.55138889 | F81: =HOUR(Tabla13[[#This Row],[Hora fin ]]-Tabla13[[#This Row],[Hora inicio]])+MINUTE(Tabla13[[#This Row],[Hora fin ]]-Tabla13[[#This Row],[Hora inicio]])/60 -> 0.73333333 | G81: Programada | H81: Mantenimiento programado | I81: Extracción | J81: Elevador de Fruto | K81: REVISION PREVENTIVA
A82: 45983 | B82: =IF(Tabla13[[#This Row],[Fecha]]="","",TEXT(Tabla13[[#This Row],[Fecha]],"aaaa")) -> sábado | C82: =IF(Tabla13[[#This Row],[Fecha]]="","",TEXT(Tabla13[[#This Row],[Fecha]],"mmmm")) -> noviembre | D82: 0.54166667 | E82: 0.56597222 | F82: =HOUR(Tabla13[[#This Row],[Hora fin ]]-Tabla13[[#This Row],[Hora inicio]])+MINUTE(Tabla13[[#This Row],[Hora fin ]]-Tabla13[[#This Row],[Hora inicio]])/60 -> 0.58333333 | G82: Programada | H82: Mantenimiento programado | I82: Extracción | J82: Elevador de Fruto | K82: REVISION PREVENTIVA
... A90: 45986 | B90: =IF(Tabla13[[#This Row],[Fecha]]="","",TEXT(Tabla13[[#This Row],[Fecha]],"aaaa")) -> martes | C90: =IF(Tabla13[[#This Row],[Fecha]]="","",TEXT(Tabla13[[#This Row],[Fecha]],"mmmm")) -> noviembre | D90: 0.82986111 | E90: 0.87222222 | F90: =HOUR(Tabla13[[#This Row],[Hora fin ]]-Tabla13[[#This Row],[Hora inicio]])+MINUTE(Tabla13[[#This Row],[Hora fin ]]-Tabla13[[#This Row],[Hora inicio]])/60 -> 1.0166667 | G90: Operativa | H90: Atascamiento | I90: Extracción | J90: Elevador de Fruto | K90: ATASCAMIENTO DEL ELEVADOR DE FRUTO
A91: 45987 | C91: =IF(Tabla13[[#This Row],[Fecha]]="","",TEXT(Tabla13[[#This Row],[Fecha]],"mmmm")) -> noviembre | D91: 0.49583333 | E91: 0.50555556 | F91: =HOUR(Tabla13[[#This Row],[Hora fin ]]-Tabla13[[#This Row],[Hora inicio]])+MINUTE(Tabla13[[#This Row],[Hora fin ]]-Tabla13[[#This Row],[Hora inicio]])/60 -> 0.23333333 | G91: Programada | H91: Mantenimiento programado | I91: Extracción | J91: Elevador de Fruto | K91: REVISION PREVENTIVA
A92: 45987 | C92: =IF(Tabla13[[#This Row],[Fecha]]="","",TEXT(Tabla13[[#This Row],[Fecha]],"mmmm")) -> noviembre | D92: 0.56805556 | E92: 0.56944444 | F92: =HOUR(Tabla13[[#This Row],[Hora fin ]]-Tabla13[[#This Row],[Hora inicio]])+MINUTE(Tabla13[[#This Row],[Hora fin ]]-Tabla13[[#This Row],[Hora inicio]])/60 -> 0.033333333 | G92: Operativa | H92: Falla eléctrica | I92: Palmistería | J92: ELEVADOR DE NUEZ | K92: DAÑO EN EL CABLE DEL SENSOR DEL ELEVADOR DE NUEZ
A93: 45988 | C93: =IF(Tabla13[[#This Row],[Fecha]]="","",TEXT(Tabla13[[#This Row],[Fecha]],"mmmm")) -> noviembre | D93: 0.0048611111 | E93: 0.047222222 | F93: =HOUR(Tabla13[[#This Row],[Hora fin ]]-Tabla13[[#This Row],[Hora inicio]])+MINUTE(Tabla13[[#This Row],[Hora fin ]]-Tabla13[[#This Row],[Hora inicio]])/60 -> 1.0166667 | G93: Programada | H93: Mantenimiento programado | I93: Extracción | J93: Elevador de Fruto | K93: REVISION PREVENTIVA
A94: 45988 | B94: =IF(Tabla13[[#This Row],[Fecha]]="","",TEXT(Tabla13[[#This Row],[Fecha]],"aaaa")) -> jueves | C94: =IF(Tabla13[[#This Row],[Fecha]]="","",TEXT(Tabla13[[#This Row],[Fecha]],"mmmm")) -> noviembre | D94: 0.46458333 | E94: 0.47986111 | F94: =HOUR(Tabla13[[#This Row],[Hora fin ]]-Tabla13[[#This Row],[Hora inicio]])+MINUTE(Tabla13[[#This Row],[Hora fin ]]-Tabla13[[#This Row],[Hora inicio]])/60 -> 0.36666667 | G94: Programada | H94: Mantenimiento programado | I94: Extracción | J94: Elevador de Fruto | K94: REVISION PREVENTIVA
A95: 45988 | B95: =IF(Tabla13[[#This Row],[Fecha]]="","",TEXT(Tabla13[[#This Row],[Fecha]],"aaaa")) -> jueves | C95: =IF(Tabla13[[#This Row],[Fecha]]="","",TEXT(Tabla13[[#This Row],[Fecha]],"mmmm")) -> noviembre | D95: 0.73125 | E95: 0.73611111 | F95: =HOUR(Tabla13[[#This Row],[Hora fin ]]-Tabla13[[#This Row],[Hora inicio]])+MINUTE(Tabla13[[#This Row],[Hora fin ]]-Tabla13[[#This Row],[Hora inicio]])/60 -> 0.11666667 | G95: Operativa | H95: Falta de fruta esterilizada | I95: Extracción | J95: Digestor Vertical | K95: NIVEL BAJO DEL DIGESTOR
A96: 45988 | B96: =IF(Tabla13[[#This Row],[Fecha]]="","",TEXT(Tabla13[[#This Row],[Fecha]],"aaaa")) -> jueves | C96: =IF(Tabla13[[#This Row],[Fecha]]="","",TEXT(Tabla13[[#This Row],[Fecha]],"mmmm")) -> noviembre | D96: 0.79166667 | E96: 0.81041667 | F96: =HOUR(Tabla13[[#This Row],[Hora fin ]]-Tabla13[[#This Row],[Hora inicio]])+MINUTE(Tabla13[[#This Row],[Hora fin ]]-Tabla13[[#This Row],[Hora inicio]])/60 -> 0.45 | G96: Operativa | H96: Falta de fruta esterilizada | I96: Esterilización | J96: Esterilizador Oblicuo Automático | K96: FALTA DE FRUTO ESTERILIZADO
A97: 45989 | B97: =IF(Tabla13[[#This Row],[Fecha]]="","",TEXT(Tabla13[[#This Row],[Fecha]],"aaaa")) -> viernes | C97: =IF(Tabla13[[#This Row],[Fecha]]="","",TEXT(Tabla13[[#This Row],[Fecha]],"mmmm")) -> noviembre | D97: 0 | E97: 0.022916667 | F97: =HOUR(Tabla13[[#This Row],[Hora fin ]]-Tabla13[[#This Row],[Hora inicio]])+MINUTE(Tabla13[[#This Row],[Hora fin ]]-Tabla13[[#This Row],[Hora inicio]])/60 -> 0.55 | G97: Programada | H97: Mantenimiento programado | I97: Extracción | J97: Elevador de Fruto | K97: REVISION PREVENTIVA
A98: 45989 | B98: =IF(Tabla13[[#This Row],[Fecha]]="","",TEXT(Tabla13[[#This Row],[Fecha]],"aaaa")) -> viernes | C98: =IF(Tabla13[[#This Row],[Fecha]]="","",TEXT(Tabla13[[#This Row],[Fecha]],"mmmm")) -> noviembre | D98: 0.24444444 | E98: 0.35625 | F98: =HOUR(Tabla13[[#This Row],[Hora fin ]]-Tabla13[[#This Row],[Hora inicio]])+MINUTE(Tabla13[[#This Row],[Hora fin ]]-Tabla13[[#This Row],[Hora inicio]])/60 -> 2.6833333 | G98: Operativa | H98: Falla operativa | I98: Clarificación | J98: Tanque de Lodos Desarenados | K98: FUGA ENN TANQUE DE LODOS, SE ROMPIO EL PISO
A99: 45989 | B99: =IF(Tabla13[[#This Row],[Fecha]]="","",TEXT(Tabla13[[#This Row],[Fecha]],"aaaa")) -> viernes | C99: =IF(Tabla13[[#This Row],[Fecha]]="","",TEXT(Tabla13[[#This Row],[Fecha]],"mmmm")) -> noviembre | D99: 0.48819444 | E99: 0.50416667 | F99: =HOUR(Tabla13[[#This Row],[Hora fin ]]-Tabla13[[#This Row],[Hora inicio]])+MINUTE(Tabla13[[#This Row],[Hora fin ]]-Tabla13[[#This Row],[Hora inicio]])/60 -> 0.38333333 | G99: Programada | H99: Mantenimiento programado | I99: Extracción | J99: Elevador de Fruto | K99: REVISION PREVENTIVA
...

Sheet Detalle1
A1: Detalles para Suma de Tiempo paro (horas) - Mes: February, Fecha: 5/6/2026 (+)
A3: Fecha | B3: Día | C3: Mes | D3: Hora inicio | E3: Hora fin | F3: Tiempo paro (horas) | G3: Tipo I | H3: Tipo II | I3: Sección | J3: Equipo | K3: Causa de falla / Observación | L3: Responsable diligenciamiento
A4: 46188 | B4: lunes | C4: junio | D4: 0.25 | E4: 0.66666667 | F4: 10 | G4: Mantenimiento | H4: Mantenimiento programado | I4: Planta general | J4: Mantenimiento programado | K4: MANTENIMIENTO PROGRAMADO EN LA PLANTA
A5: 46187 | B5: domingo | C5: junio | D5: 0.25 | E5: 0.66666667 | F5: 10 | G5: Mantenimiento | H5: Mantenimiento programado | I5: Planta general | J5: Mantenimiento programado | K5: MANTENIMIENTO PROGRAMADO EN LA PLANTA
A6: 46182 | B6: martes | C6: junio | D6: 0.25 | E6: 0.75 | F6: 12 | G6: Mantenimiento | H6: Mantenimiento programado | I6: Planta general | J6: Mantenimiento programado | K6: MANTENIMIENTO PROGRAMADO EN LA PLANTA
A7: 46181 | B7: lunes | C7: junio | D7: 0.25 | E7: 0.75 | F7: 12 | G7: Mantenimiento | H7: Mantenimiento programado | I7: Planta general | J7: Mantenimiento programado | K7: MANTENIMIENTO PROGRAMADO EN LA PLANTA
A8: 46180 | B8: domingo | C8: junio | D8: 0.25 | E8: 0.75 | F8: 12 | G8: Mantenimiento | H8: Mantenimiento programado | I8: Planta general | J8: Mantenimiento programado | K8: MANTENIMIENTO PROGRAMADO EN LA PLANTA
A9: 46179 | B9: sábado | C9: junio | D9: 0.5 | E9: 0.75 | F9: 6 | G9: Mantenimiento | H9: Mantenimiento programado | I9: Planta general | J9: Mantenimiento programado | K9: MANTENIMIENTO PROGRAMADO EN LA PLANTA
A10: 46192 | B10: viernes | C10: junio | D10: 0.65 | E10: 1 | F10: 8.4 | G10: Operativa | H10: Falla mecánica | I10: Extracción | J10: Prensa de doble tornillo | K10: SE ROMPIO EL EJE LARGO DE LA PRENSA P 15
A11: 46190 | B11: miércoles | C11: junio | D11: 0.34791667 | E11: 0.34930556 | F11: 0.033333333 | G11: Programada | H11: Mantenimiento programado | I11: Extracción | J11: Prensa de doble tornillo | K11: AJUSTE DE PARAMETROS DEL VARIADOR DE LA PRENSA P15
A12: 46178 | B12: viernes | C12: junio | D12: 0.38263889 | E12: 0.39236111 | F12: 0.23333333 | G12: Mantenimiento | H12: Mantenimiento programado | I12: Extracción | J12: Prensa de doble tornillo | K12: AJUSTE EN EL VARIADOR DE LA PRENSA P15
A13: 46183 | B13: miércoles | C13: junio | D13: 0.53333333 | E13: 0.57638889 | F13: 1.0333333 | G13: Operativa | H13: Falla eléctrica | I13: Generacion electrica | J13: Planta eléctrica de 1250 Kva | K13: SE APAGO EL GENERADOR POR BAJO NIVEL DE REFRIGERANTE
A14: 46178 | B14: viernes | C14: junio | D14: 0.60902778 | E14: 0.66388889 | F14: 1.3166667 | G14: Programada | H14: Falla eléctrica | I14: Esterilización | J14: Esterilizador Oblicuo Automático | K14: FALLA EN LOS CENSORES DE LA PUERTA INFERIOR DEL ESTERILIZADOR
A15: 46178 | B15: viernes | C15: junio | D15: 0.42430556 | E15: 0.45277778 | F15: 0.68333333 | G15: Operativa | H15: Falta de fruta esterilizada | I15: Esterilización | J15: Esterilizador Oblicuo Automático | K15: FALTA DE FRUTO ESTERILIZADO
... A55: 46183 | B55: miércoles | C55: junio | D55: 0.26875 | E55: 0.29375 | F55: 0.6 | G55: Operativa | H55: Falla mecánica | I55: Clarificación | J55: Filtro Cepillo | K55: SE ROMPIO EL FILTRO CEPILLO

Sheet Resumen general
A2: #VALUE! | B2: INDICADOR DE PARADAS CPO Resumen general | F2: Código:
F3: Versión:
F4: Fecha de Aprobación:
A6: RESUMEN HORAS DE PAROS POR SECCIÓN Y EQUIPO | D6: HORAS TOTALES POR TIPO DE PARO
D7: Desde
D8: Año | E8: Mes | F8: Dia
A9: Mes | B9: junio | D9: 2026 | E9: 6 | F9: 1
A10: Fecha | B10: (Todas)
D11: Año | E11: Mes | F11: Dia
B12: Suma de Tiempo paro (horas) | D12: 2026 | E12: 6 | F12: 30
A13: Mantenimiento programado | B13: 62
A14: Prensa de doble tornillo | B14: 8.6666667 | D14: Tipo parada | E14: Horas de paro | F14: Porcentaje (%)
A15: Planta eléctrica de 1250 Kva | B15: 1.0333333 | D15: Programada | E15: =(SUMIFS('Registrio Paros'!F:F,'Registrio Paros'!A:A,">="&DATE($D$9,$E$9,$F$9),'Registrio Paros'!G:G,'Resumen general'!D15)-SUMIFS('Registrio Paros'!F:F,'Registrio Paros'!A:A,">"&DATE($D$12,$E$12,$F$12),'Registrio Paros'!G:G,'Resumen general'!D15)) -> 63.783333 | F15: =E15/$E$23 -> 0.68682699 | G15: Mtto Programado
A16: Esterilizador Oblicuo Automático | B16: 5.0333333 | D16: Mantenimiento | E16: =+E17+E18 -> 21.366667 | F16: =E16/E23 -> 0.23007897 | G16: Mto no programado
A17: Banda #1 para Racimos Vacíos | B17: 0.3 | D17: Falla mecánica | E17: =(SUMIFS('Registrio Paros'!F:F,'Registrio Paros'!A:A,">="&DATE($D$9,$E$9,$F$9),'Registrio Paros'!H:H,'Resumen general'!D17)-SUMIFS('Registrio Paros'!F:F,'Registrio Paros'!A:A,">"&DATE($D$12,$E$12,$F$12),'Registrio Paros'!H:H,'Resumen general'!D17)) -> 18.95 | F17: =E17/$E$23 -> 0.20405599 | G17: Mecánica
A18: Elevador de Fruto | B18: 2.5 | D18: Falla eléctrica | E18: =(SUMIFS('Registrio Paros'!F:F,'Registrio Paros'!A:A,">="&DATE($D$9,$E$9,$F$9),'Registrio Paros'!H:H,'Resumen general'!D18)-SUMIFS('Registrio Paros'!F:F,'Registrio Paros'!A:A,">"&DATE($D$12,$E$12,$F$12),'Registrio Paros'!H:H,'Resumen general'!D18)) -> 2.4166667 | F18: =E18/$E$23 -> 0.026022972 | G18: Eléctrica
A19: Prensa para Racimos Vacíos | B19: 5.6 | D19: Operativa | E19: =(SUMIFS('Registrio Paros'!F:F,'Registrio Paros'!A:A,">="&DATE($D$9,$E$9,$F$9),'Registrio Paros'!G:G,'Resumen general'!D19)-SUMIFS('Registrio Paros'!F:F,'Registrio Paros'!A:A,">"&DATE($D$12,$E$12,$F$12),'Registrio Paros'!G:G,'Resumen general'!D19)) -> 7.7166667 | F19: =E19/$E$23 -> 0.083094042 | G19: Operativa
A20: Turbina | B20: 1.5833333 | D20: Externa | E20: =(SUMIFS('Registrio Paros'!F:F,'Registrio Paros'!A:A,">="&DATE($D$9,$E$9,$F$9),'Registrio Paros'!G:G,'Resumen general'!D20)-SUMIFS('Registrio Paros'!F:F,'Registrio Paros'!A:A,">"&DATE($D$12,$E$12,$F$12),'Registrio Paros'!G:G,'Resumen general'!D20)) -> 0 | F20: =E20/E23 -> 0 | G20: Otras-Externa
A21: Sinfín para Fruto Suelto | B21: 5.35 | D21: Falta de fruta fresca | E21: =(SUMIFS('Registrio Paros'!F:F,'Registrio Paros'!A:A,">="&DATE($D$9,$E$9,$F$9),'Registrio Paros'!H:H,'Resumen general'!D21)-SUMIFS('Registrio Paros'!F:F,'Registrio Paros'!A:A,">"&DATE($D$12,$E$12,$F$12),'Registrio Paros'!H:H,'Resumen general'!D21)) -> 0 | F21: =E21/E23 -> 0 | G21: Falta RFF
A22: Molino tipo Ripple Mill | B22: 0.2 | D22: Falta energía red | E22: =(SUMIFS('Registrio Paros'!F:F,'Registrio Paros'!A:A,">="&DATE($D$9,$E$9,$F$9),'Registrio Paros'!H:H,'Resumen general'!D22)-SUMIFS('Registrio Paros'!F:F,'Registrio Paros'!A:A,">"&DATE($D$12,$E$12,$F$12),'Registrio Paros'!H:H,'Resumen general'!D22)) -> 0 | F22: =E22/E23 -> 0 | G22: Corte energia red
A23: Filtro Cepillo | B23: 0.6 | D23: Total | E23: =E15+E16+E19+E20 -> 92.866667 | F23: =SUM(F15+F16+F19+F20) -> 1
A24: Total general | B24: 92.866667
A36: EQUIPO | B36: HORAS
A37: Prensa de doble tornillo | B37: 8.6666667
A38: Prensa para Racimos Vacíos | B38: 5.6
A39: Sinfín para Fruto Suelto | B39: 5.35
A40: Esterilizador Oblicuo Automático | B40: 5.0333333
A41: Elevador de Fruto | B41: 2.5
A42: Turbina | B42: 1.5833333
A43: Planta eléctrica de 1250 Kva | B43: 1.0333333
A44: Filtro Cepillo | B44: 0.6
A45: Banda #1 para Racimos Vacíos | B45: 0.3
A46: Molino tipo Ripple Mill | B46: 0.2
A58: total | B58: =SUBTOTAL(109,Tabla1[HORAS]) -> 30.866667

Sheet MTBF
D2: MTBF (Tiempo Medio Entre Fallos) | G2: TIEMPO TOTAL DE FUNCIONAMIENTO DE LA PLANNTA | H2: =+B6/B11 -> 45.933333
G3: NUMERO DE FALLAS
A5: HORAS TOTALES PROGRAMADAS | B5: 452
A6: HORAS EFECTIVAS DE PROCESO | B6: 413.4
A7: HOROMETRO INICIAL | B7: 10923.15
A8: HOROMETRO FINAL | B8: 11293.26
A9: HORAS EFECTIVAS DE LA PRENSA | B9: =+B8-B7 -> 370.11
A10: HORAS NO PROCESADAS | B10: =+B5-B6 -> 38.6
A11: CANTIDAD DE FALLAS | B11: 9
A12: EFICIENCIA DE PLANTA | B12: =100%-(B10/B5) -> 0.91460177
A17: HORAS NO PROCESADAS
A18: TIPO DE PARADA | B18: TIEMPO/ HORAS
A19: CAMBIO DE ENERGIA | B19: 1.52
A20: MANTENIMIENTO PROGRAMADO | B20: 8
A21: FALLA ELECTRICA | B21: 2.42
A22: FALLA MECANICA | B22: 18.95
A23: ATASCAMIENTO | B23: 4
A24: FALTA DE FRUTA ESTERILIZADA | B24: 3.72
A25: TOTAL | B25: =SUM(B19:B24) -> 38.61

Sheet MTTR
C2: MTTR (Tiempo Medio de Reparación) | F2: TIEMPO TOTAL DE HORAS PARADAS POR REPARACION | G2: =+(C21+C22)/C11 -> 2.3744444
F3: NUMERO DE FALLAS
B5: HORAS TOTALES PROGRAMADAS | C5: 452 | E5: TIEMPO TOTAL DE HORAS PARADAS POR REPARACION
B6: HORAS EFECTIVAS DE PROCESO | C6: 413.4 | E6: TIPO DE FALLA | F6: Tiempo paro (horas) | G6: Equipo | H6: Causa de falla / Observación | I6: PLAN DE ACCION
B7: HOROMETRO INICIAL | C7: 10923.15 | E7: ELECTRICA | F7: 1.3166667 | G7: Esterilizador Oblicuo Automático | H7: FALLA EN LOS CENSORES DE LA PUERTA INFERIOR DEL ESTERILIZADOR | I7: Se evidencio que estaban llegando sensores que no correspondian a los solicitados, ahora si llega la refencia correcta.
B8: HOROMETRO FINAL | C8: 11293.26 | E8: ELECTRICA | F8: 0.066666667 | G8: Turbina | H8: APAGON DE TODOS LOS EQUIPOS DE LA PLANTA | I8: Imprevisto electrico - N/A
B9: HORAS EFECTIVAS DE LA PRENSA | C9: =+C8-C7 -> 370.11 | E9: ELECTRICA | F9: 1.0333333 | G9: Planta eléctrica de 1250 Kva | H9: SE APAGO EL GENERADOR POR BAJO NIVEL DE REFRIGERANTE | I9: El nuevo radiador llega a finales del mes de julio 2026
B10: HORAS NO PROCESADAS | C10: =+C5-C6 -> 38.6 | E10: MECANICA | F10: 1.4 | G10: Elevador de Fruto | H10: SE ROMPIO CADENA DE TRASMISION DEL ELEVADOR DE FRUTO | I10: Ya se pidio el nuevo sistema de trasmision con cadena 100 paso doble
B11: CANTIDAD DE FALLAS | C11: 9 | E11: MECANICA | F11: 0.6 | G11: Filtro Cepillo | H11: SE ROMPIO EL FILTRO CEPILLO | I11: N/A
B12: EFICIENCIA DE PLANTA | C12: =100%-(C10/C5) -> 0.91460177 | E12: MECANICA | F12: 5.6 | G12: Prensa para Racimos Vacíos | H12: SE ROMPIERON LOS RODAMEINTOS DEL EJE MOTRIZ DE LA PRENSA RAQUIS | I12: Se cambio completo el eje motriz de la prensa raquis
E13: MECANICA | F13: 8.4 | G13: Prensa de doble tornillo | H13: SE ROMPIO EL EJE LARGO DE LA PRENSA P 15 | I13: A finales del mes de julio se va a cambiar el sistema de sujeción entre tornillos y ejes de cuadrado a circular.
E14: MECANICA | F14: 2.95 | G14: Sinfín para Fruto Suelto | H14: SE ROMPIO ALAVE DEL SINFÍN BAJO DESFRUTADOR | I14: Se debe modificar el sinfín para fruto suelto, pasar de cinta a sinfín continuo
E16: Suma de Tiempo paro (horas) | F16: Etiquetas de columna
B17: HORAS NO PROCESADAS | E17: Etiquetas de fila | F17: ELECTRICA | G17: MECANICA | H17: Total general
B18: TIPO DE PARADA | C18: TIEMPO/ HORAS | E18: Prensa de doble tornillo | G18: 8.4 | H18: 8.4
B19: CAMBIO DE ENERGIA | C19: 1.52 | E19: Prensa para Racimos Vacíos | G19: 5.6 | H19: 5.6
B20: MANTENIMIENTO PROGRAMADO | C20: 8 | E20: Sinfín para Fruto Suelto | G20: 2.95 | H20: 2.95
B21: FALLA ELECTRICA | C21: 2.42 | E21: Elevador de Fruto | G21: 1.4 | H21: 1.4
B22: FALLA MECANICA | C22: 18.95 | E22: Filtro Cepillo | G22: 0.6 | H22: 0.6
B23: ATASCAMIENTO | C23: 4 | E23: Esterilizador Oblicuo Automático | F23: 1.3166667 | H23: 1.3166667
B24: FALTA DE FRUTA ESTERILIZADA | C24: 3.72 | E24: Turbina | F24: 0.066666667 | H24: 0.066666667
B25: TOTAL | C25: =SUM(C19:C24) -> 38.61 | E25: Planta eléctrica de 1250 Kva | F25: 1.0333333 | H25: 1.0333333
E26: Total general | F26: 2.4166667 | G26: 18.95 | H26: 21.366667

Sheet Análisis PNP por equipo
B2: #VALUE! | C2: CONTROL DE PAROS CPO Análisis Paradas No Programadas por equipo | D2: Código:
D3: Versión:
D4: Fecha de Aprobación:
B6: HORAS TOTALES POR EQUIPO
B7: Desde
B8: Año | C8: Mes | D8: Dia
B9: 2026 | C9: 6 | D9: 1
B10: Hasta
B11: Año | C11: Mes | D11: Dia
B12: 2026 | C12: 6 | D12: 31
B14: Equipo | C14: Horas de paro | D14: Porcentaje sobre total de paradas (%)
B15: =Listas!D2 -> Nave esterilización | C15: =(SUMIFS('Registrio Paros'!F:F,'Registrio Paros'!A:A,">="&DATE($B$9,$C$9,$D$9),'Registrio Paros'!J:J,B15,'Registrio Paros'!G:G,"<>Programada")-SUMIFS('Registrio Paros'!F:F,'Registrio Paros'!A:A,">"&DATE($B$12,$C$12,$D$12),'Registrio Paros'!J:J,B15,'Registrio Paros'!G:G,"<>Programada")) -> 0 | D15: =IFERROR(C15/SUM($C$15:$C$152),"") -> 0
B16: =Listas!D3 -> Nave central | C16: =(SUMIFS('Registrio Paros'!F:F,'Registrio Paros'!A:A,">="&DATE($B$9,$C$9,$D$9),'Registrio Paros'!J:J,B16,'Registrio Paros'!G:G,"<>Programada")-SUMIFS('Registrio Paros'!F:F,'Registrio Paros'!A:A,">"&DATE($B$12,$C$12,$D$12),'Registrio Paros'!J:J,B16,'Registrio Paros'!G:G,"<>Programada")) -> 0 | D16: =IFERROR(C16/SUM($C$15:$C$152),"") -> 0
B17: =Listas!D4 -> Nave caldera | C17: =(SUMIFS('Registrio Paros'!F:F,'Registrio Paros'!A:A,">="&DATE($B$9,$C$9,$D$9),'Registrio Paros'!J:J,B17,'Registrio Paros'!G:G,"<>Programada")-SUMIFS('Registrio Paros'!F:F,'Registrio Paros'!A:A,">"&DATE($B$12,$C$12,$D$12),'Registrio Paros'!J:J,B17,'Registrio Paros'!G:G,"<>Programada")) -> 0 | D17: =IFERROR(C17/SUM($C$15:$C$152),"") -> 0
B18: =Listas!D5 -> Nave CCM | C18: =(SUMIFS('Registrio Paros'!F:F,'Registrio Paros'!A:A,">="&DATE($B$9,$C$9,$D$9),'Registrio Paros'!J:J,B18,'Registrio Paros'!G:G,"<>Programada")-SUMIFS('Registrio Paros'!F:F,'Registrio Paros'!A:A,">"&DATE($B$12,$C$12,$D$12),'Registrio Paros'!J:J,B18,'Registrio Paros'!G:G,"<>Programada")) -> 0 | D18: =IFERROR(C18/SUM($C$15:$C$152),"") -> 0
B19: =Listas!D6 -> Nave florentino | C19: =(SUMIFS('Registrio Paros'!F:F,'Registrio Paros'!A:A,">="&DATE($B$9,$C$9,$D$9),'Registrio Paros'!J:J,B19,'Registrio Paros'!G:G,"<>Programada")-SUMIFS('Registrio Paros'!F:F,'Registrio Paros'!A:A,">"&DATE($B$12,$C$12,$D$12),'Registrio Paros'!J:J,B19,'Registrio Paros'!G:G,"<>Programada")) -> 0 | D19: =IFERROR(C19/SUM($C$15:$C$152),"") -> 0
B20: =Listas!D7 -> Comedor | C20: =(SUMIFS('Registrio Paros'!F:F,'Registrio Paros'!A:A,">="&DATE($B$9,$C$9,$D$9),'Registrio Paros'!J:J,B20,'Registrio Paros'!G:G,"<>Programada")-SUMIFS('Registrio Paros'!F:F,'Registrio Paros'!A:A,">"&DATE($B$12,$C$12,$D$12),'Registrio Paros'!J:J,B20,'Registrio Paros'!G:G,"<>Programada")) -> 0 | D20: =IFERROR(C20/SUM($C$15:$C$152),"") -> 0
B21: =Listas!D8 -> Contenedor de Laboratorio | C21: =(SUMIFS('Registrio Paros'!F:F,'Registrio Paros'!A:A,">="&DATE($B$9,$C$9,$D$9),'Registrio Paros'!J:J,B21,'Registrio Paros'!G:G,"<>Programada")-SUMIFS('Registrio Paros'!F:F,'Registrio Paros'!A:A,">"&DATE($B$12,$C$12,$D$12),'Registrio Paros'!J:J,B21,'Registrio Paros'!G:G,"<>Programada")) -> 0 | D21: =IFERROR(C21/SUM($C$15:$C$152),"") -> 0
B22: =Listas!D9 -> Unidad hidráulica tolva recepción | C22: =(SUMIFS('Registrio Paros'!F:F,'Registrio Paros'!A:A,">="&DATE($B$9,$C$9,$D$9),'Registrio Paros'!J:J,B22,'Registrio Paros'!G:G,"<>Programada")-SUMIFS('Registrio Paros'!F:F,'Registrio Paros'!A:A,">"&DATE($B$12,$C$12,$D$12),'Registrio Paros'!J:J,B22,'Registrio Paros'!G:G,"<>Programada")) -> 0 | D22: =IFERROR(C22/SUM($C$15:$C$152),"") -> 0
B23: =Listas!D10 -> Redler #1 | C23: =(SUMIFS('Registrio Paros'!F:F,'Registrio Paros'!A:A,">="&DATE($B$9,$C$9,$D$9),'Registrio Paros'!J:J,B23,'Registrio Paros'!G:G,"<>Programada")-SUMIFS('Registrio Paros'!F:F,'Registrio Paros'!A:A,">"&DATE($B$12,$C$12,$D$12),'Registrio Paros'!J:J,B23,'Registrio Paros'!G:G,"<>Programada")) -> 0 | D23: =IFERROR(C23/SUM($C$15:$C$152),"") -> 0
B24: =Listas!D11 -> Bomba Centrifuga del Foso de Tolvas | C24: =(SUMIFS('Registrio Paros'!F:F,'Registrio Paros'!A:A,">="&DATE($B$9,$C$9,$D$9),'Registrio Paros'!J:J,B24,'Registrio Paros'!G:G,"<>Programada")-SUMIFS('Registrio Paros'!F:F,'Registrio Paros'!A:A,">"&DATE($B$12,$C$12,$D$12),'Registrio Paros'!J:J,B24,'Registrio Paros'!G:G,"<>Programada")) -> 0 | D24: =IFERROR(C24/SUM($C$15:$C$152),"") -> 0
B25: =Listas!D12 -> Redler #2 de Fruta a Esterilizadores | C25: =(SUMIFS('Registrio Paros'!F:F,'Registrio Paros'!A:A,">="&DATE($B$9,$C$9,$D$9),'Registrio Paros'!J:J,B25,'Registrio Paros'!G:G,"<>Programada")-SUMIFS('Registrio Paros'!F:F,'Registrio Paros'!A:A,">"&DATE($B$12,$C$12,$D$12),'Registrio Paros'!J:J,B25,'Registrio Paros'!G:G,"<>Programada")) -> 0 | D25: =IFERROR(C25/SUM($C$15:$C$152),"") -> 0
B26: =Listas!D13 -> Esterilizador Oblicuo Automático | C26: =(SUMIFS('Registrio Paros'!F:F,'Registrio Paros'!A:A,">="&DATE($B$9,$C$9,$D$9),'Registrio Paros'!J:J,B26,'Registrio Paros'!G:G,"<>Programada")-SUMIFS('Registrio Paros'!F:F,'Registrio Paros'!A:A,">"&DATE($B$12,$C$12,$D$12),'Registrio Paros'!J:J,B26,'Registrio Paros'!G:G,"<>Programada")) -> 5.0333333 | D26: =IFERROR(C26/SUM($C$15:$C$152),"") -> 0.1730659
... B152: =Listas!D139 -> Flujómetro de efluente final | C152: =(SUMIFS('Registrio Paros'!F:F,'Registrio Paros'!A:A,">="&DATE($B$9,$C$9,$D$9),'Registrio Paros'!J:J,B152,'Registrio Paros'!G:G,"<>Programada")-SUMIFS('Registrio Paros'!F:F,'Registrio Paros'!A:A,">"&DATE($B$12,$C$12,$D$12),'Registrio Paros'!J:J,B152,'Registrio Paros'!G:G,"<>Programada")) -> 0 | D152: =IFERROR(C152/SUM($C$15:$C$152),"") -> 0

Sheet Listas
A1: TIPO I | B1: TIPO II | C1: SECCIÓN | D1: EQUIPOS
A2: Programada | B2: Arranque planta | C2: Planta general | D2: Nave esterilización
A3: Mantenimiento | B3: Apagado planta | C3: Recepción fruta | D3: Nave central
A4: Operativa | B4: Reunión | C4: Esterilización | D4: Nave caldera
A5: Externa | B5: Capacitaciones | C5: Desfrutado | D5: Nave CCM
B6: Mantenimiento programado | C6: Extracción | D6: Nave florentino
B7: Montajes | C7: Clarificación | D7: Comedor
B8: Falla eléctrica | C8: Desfibrado | D8: Contenedor de Laboratorio
B9: Falla mecánica | C9: Palmistería | D9: Unidad hidráulica tolva recepción
B10: Falla operativa | C10: Generación de vapor | D10: Redler #1
B11: Atascamiento | C11: Planta tratamiento de agua | D11: Bomba Centrifuga del Foso de Tolvas
B12: Sobrecarga | C12: Tratamiento efluentes | D12: Redler #2 de Fruta a Esterilizadores
B13: Falta de fruta esterilizada | C13: Raquis | D13: Esterilizador Oblicuo Automático
B14: Falta de fruta fresca | C14: Generacion electrica | D14: Unidad hidraulica llenado esterilizador
B15: Falta energía red | D15: Unidad hidraulica descarga esterilizador
B16: Eventos naturales | D16: Tolva para Fruto Esterilizado Dosificador
B17: Eventos orden público | D17: Redler de Fruto Esterilizado
D18: Bomba para Chimenea de Esterilización
D19: Sensor de Presión Valvula de Alivio
D20: Bomba Foso de Condensados del Esterilizador
D21: Tapa Superior del Autoclave
D22: Tapa Inferior del Autoclave
D23: Dosificador de Fruto Cosido
D24: Desfrutador Sin Eje
D25: Sinfín para Fruto Suelto
D26: Hidroacople de Desfrutador
D27: Motor de Desfrutador
D28: Banda #1 para Racimos Vacíos
D29: Crusher para Racimos Vacíos
... D141: Mantenimiento programado

Sheet Pareto ago. 2017
A1: Equipo | B1: 2016 | C1: 2017 | D1: Total | E1: 2016 | F1: 2017
A2: Prensa 2 | B2: 86.76 | C2: 118.56667 | D2: =SUM(B2:C2) -> 205.32667 | E2: =B2/$B$95 -> 0.094937955 | F2: =C2/$C$95 -> 0.15719949 | G2: =D2/$D$95 -> 0.1230899 | H2: =G2+H1 -> 0.1230899
A3: Prensa 1 | B3: 88.57 | C3: 85.85 | D3: =SUM(B3:C3) -> 174.42 | E3: =B3/$B$95 -> 0.096918565 | F3: =C3/$C$95 -> 0.11382268 | G3: =D3/$D$95 -> 0.10456187 | H3: =G3+H2 -> 0.22765176
A4: Falta de fruta esterilizado | C4: 160.44167 | D4: =SUM(B4:C4) -> 160.44167 | E4: =B4/$B$95 -> 0 | F4: =C4/$C$95 -> 0.21271871 | G4: =D4/$D$95 -> 0.096182091 | H4: =G4+H3 -> 0.32383386
A5: Desfrutador | B5: 64.85 | C5: 72.125 | D5: =SUM(B5:C5) -> 136.975 | E5: =B5/$B$95 -> 0.07096273 | F5: =C5/$C$95 -> 0.095625638 | G5: =D5/$D$95 -> 0.082114218 | H5: =G5+H4 -> 0.40594807
A6: Caldera | B6: 67.958333 | C6: 15.141667 | D6: =SUM(B6:C6) -> 83.1 | E6: =B6/$B$95 -> 0.074364053 | F6: =C6/$C$95 -> 0.020075307 | G6: =D6/$D$95 -> 0.049817058 | H6: =G6+H5 -> 0.45576513
A7: Elevador de fruto | B7: 23.475 | C7: 42.633333 | D7: =SUM(B7:C7) -> 66.108333 | E7: =B7/$B$95 -> 0.025687742 | F7: =C7/$C$95 -> 0.056524641 | G7: =D7/$D$95 -> 0.039630838 | H7: =G7+H6 -> 0.49539597
A8: Arranque | B8: 59.741667 | C8: 3.825 | D8: =SUM(B8:C8) -> 63.566667 | E8: =B8/$B$95 -> 0.065372887 | F8: =C8/$C$95 -> 0.0050713077 | G8: =D8/$D$95 -> 0.038107152 | H8: =G8+H7 -> 0.53350312
A9: Redler # 2 | B9: 20.46 | C9: 24.29 | D9: =SUM(B9:C9) -> 44.75 | E9: =B9/$B$95 -> 0.02238855 | F9: =C9/$C$95 -> 0.032204461 | G9: =D9/$D$95 -> 0.026826875 | H9: =G9+H8 -> 0.56033
A10: Limpieza parrilla caldera | B10: 44.716667 | D10: =SUM(B10:C10) -> 44.716667 | E10: =B10/$B$95 -> 0.048931638 | F10: =C10/$C$95 -> 0 | G10: =D10/$D$95 -> 0.026806892 | H10: =G10+H9 -> 0.58713689
A11: Redler Principal | B11: 25.71 | C11: 17.875 | D11: =SUM(B11:C11) -> 43.585 | E11: =B11/$B$95 -> 0.028133412 | F11: =C11/$C$95 -> 0.023699248 | G11: =D11/$D$95 -> 0.026128477 | H11: =G11+H10 -> 0.61326537
A12: Autoclave # 1 | B12: 38.75 | C12: 4.025 | D12: =SUM(B12:C12) -> 42.775 | E12: =B12/$B$95 -> 0.042402556 | F12: =C12/$C$95 -> 0.0053364741 | G12: =D12/$D$95 -> 0.025642896 | H12: =G12+H11 -> 0.63890826
A13: Digestor 2 | B13: 29.82 | C13: 8.37 | D13: =SUM(B13:C13) -> 38.19 | E13: =B13/$B$95 -> 0.032630819 | F13: =C13/$C$95 -> 0.011097214 | G13: =D13/$D$95 -> 0.022894265 | H13: =G13+H12 -> 0.66180253
A14: Falta de Fruta en planta | B14: 33.97 | C14: 0.35833333 | D14: =SUM(B14:C14) -> 34.328333 | E14: =B14/$B$95 -> 0.037171996 | F14: =C14/$C$95 -> 0.00047508983 | G14: =D14/$D$95 -> 0.020579261 | H14: =G14+H13 -> 0.68238179
A15: Fluído eléctrico | C15: 34.208333 | D15: =SUM(B15:C15) -> 34.208333 | E15: =B15/$B$95 -> 0 | F15: =C15/$C$95 -> 0.045354505 | G15: =D15/$D$95 -> 0.020507323 | H15: =G15+H14 -> 0.70288911
A16: Parrilla viajera | B16: 33.1 | D16: =SUM(B16:C16) -> 33.1 | E16: =B16/$B$95 -> 0.03621999 | F16: =C16/$C$95 -> 0 | G16: =D16/$D$95 -> 0.019842895 | H16: =G16+H15 -> 0.72273201
A17: Transportador de torta | B17: 13.53 | C17: 16.83 | D17: =SUM(B17:C17) -> 30.36 | E17: =B17/$B$95 -> 0.014805331 | F17: =C17/$C$95 -> 0.022313754 | G17: =D17/$D$95 -> 0.018200311 | H17: =G17+H16 -> 0.74093232
A18: Redler caldera | B18: 25.183333 | C18: 3.4166667 | D18: =SUM(B18:C18) -> 28.6 | E18: =B18/$B$95 -> 0.027557102 | F18: =C18/$C$95 -> 0.0045299262 | G18: =D18/$D$95 -> 0.017145221 | H18: =G18+H17 -> 0.75807754
A19: Bomba bocatoma | B19: 25.733333 | D19: =SUM(B19:C19) -> 25.733333 | E19: =B19/$B$95 -> 0.028158945 | F19: =C19/$C$95 -> 0 | G19: =D19/$D$95 -> 0.015426702 | H19: =G19+H18 -> 0.77350424
A20: redler alimenta tolvas | B20: 16.77 | C20: 3.22 | D20: =SUM(B20:C20) -> 19.99 | E20: =B20/$B$95 -> 0.018350732 | F20: =C20/$C$95 -> 0.0042691793 | G20: =D20/$D$95 -> 0.01198367 | H20: =G20+H19 -> 0.78548791
A21: Planta en General | B21: 15.04 | C21: 4.6666667 | D21: =SUM(B21:C21) -> 19.706667 | E21: =B21/$B$95 -> 0.016457663 | F21: =C21/$C$95 -> 0.0061872163 | G21: =D21/$D$95 -> 0.011813816 | H21: =G21+H20 -> 0.79730173
A22: Redler Transversal de fruto cocido | C22: 17.625 | D22: =SUM(B22:C22) -> 17.625 | E22: =B22/$B$95 -> 0 | F22: =C22/$C$95 -> 0.02336779 | G22: =D22/$D$95 -> 0.010565892 | H22: =G22+H21 -> 0.80786762
A23: Filtro cepillo #1 | B23: 12.066667 | C23: 4.78 | D23: =SUM(B23:C23) -> 16.846667 | E23: =B23/$B$95 -> 0.013204065 | F23: =C23/$C$95 -> 0.0063374773 | G23: =D23/$D$95 -> 0.010099294 | H23: =G23+H22 -> 0.81796691
A24: Digestor 1 | B24: 0.425 | C24: 15.38 | D24: =SUM(B24:C24) -> 15.805 | E24: =B24/$B$95 -> 0.00046506029 | F24: =C24/$C$95 -> 0.020391297 | G24: =D24/$D$95 -> 0.0094748327 | H24: =G24+H23 -> 0.82744175
A25: Transportador de fruto bajo desfrutador | B25: 11.28 | C25: 4.01 | D25: =SUM(B25:C25) -> 15.29 | E25: =B25/$B$95 -> 0.012343247 | F25: =C25/$C$95 -> 0.0053165866 | G25: =D25/$D$95 -> 0.0091660988 | H25: =G25+H24 -> 0.83660784
A26: bomba a florentinos | B26: 13.55 | C26: 1.45 | D26: =SUM(B26:C26) -> 15 | E26: =B26/$B$95 -> 0.014827216 | F26: =C26/$C$95 -> 0.0019224565 | G26: =D26/$D$95 -> 0.0089922487 | H26: =G26+H25 -> 0.84560009
A27: Vagoneta | B27: 0.75 | C27: 13.583333 | D27: =SUM(B27:C27) -> 14.333333 | E27: =B27/$B$95 -> 0.00082069464 | F27: =C27/$C$95 -> 0.018009219 | G27: =D27/$D$95 -> 0.0085925932 | H27: =G27+H26 -> 0.85419269
A28: Compresor esterilizacion | C28: 12.441667 | D28: =SUM(B28:C28) -> 12.441667 | E28: =B28/$B$95 -> 0 | F28: =C28/$C$95 -> 0.016495561 | G28: =D28/$D$95 -> 0.0074585707 | H28: =G28+H27 -> 0.86165126
A29: Planta eléctrica | B29: 4.1416667 | C29: 8.01 | D29: =SUM(B29:C29) -> 12.151667 | E29: =B29/$B$95 -> 0.0045320582 | F29: =C29/$C$95 -> 0.010619915 | G29: =D29/$D$95 -> 0.0072847206 | H29: =G29+H28 -> 0.86893598
A30: Vagoneta #1 | B30: 8.1333333 | C30: 2.7333333 | D30: =SUM(B30:C30) -> 10.866667 | E30: =B30/$B$95 -> 0.0088999774 | F30: =C30/$C$95 -> 0.003623941 | G30: =D30/$D$95 -> 0.0065143846 | H30: =G30+H29 -> 0.87545036
A31: Bomba tanque elevado | B31: 9.5 | D31: =SUM(B31:C31) -> 9.5 | E31: =B31/$B$95 -> 0.010395465 | F31: =C31/$C$95 -> 0 | G31: =D31/$D$95 -> 0.0056950908 | H31: =G31+H30 -> 0.88114545
A32: Clarificador | B32: 9.25 | D32: =SUM(B32:C32) -> 9.25 | E32: =B32/$B$95 -> 0.010121901 | F32: =C32/$C$95 -> 0 | G32: =D32/$D$95 -> 0.00554522 | H32: =G32+H31 -> 0.88669067
A33: Transportador Sinfín distribuidor fruto | B33: 8.63 | D33: =SUM(B33:C33) -> 8.63 | E33: =B33/$B$95 -> 0.0094434596 | F33: =C33/$C$95 -> 0 | G33: =D33/$D$95 -> 0.0051735404 | H33: =G33+H32 -> 0.89186421
A34: ventilador aire primario | B34: 8.6 | D34: =SUM(B34:C34) -> 8.6 | E34: =B34/$B$95 -> 0.0094106318 | F34: =C34/$C$95 -> 0 | G34: =D34/$D$95 -> 0.0051555559 | H34: =G34+H33 -> 0.89701977
A35: Centrifuga 3 | B35: 7.99 | D35: =SUM(B35:C35) -> 7.99 | E35: =B35/$B$95 -> 0.0087431335 | F35: =C35/$C$95 -> 0 | G35: =D35/$D$95 -> 0.0047898711 | H35: =G35+H34 -> 0.90180964
A36: Transportador de fibra a calderas | B36: 5.08 | C36: 2.64 | D36: =SUM(B36:C36) -> 7.72 | E36: =B36/$B$95 -> 0.0055588383 | F36: =C36/$C$95 -> 0.0035001967 | G36: =D36/$D$95 -> 0.0046280107 | H36: =G36+H35 -> 0.90643765
A37: Válvula modulante distribuidor | B37: 7.4416667 | D37: =SUM(B37:C37) -> 7.4416667 | E37: =B37/$B$95 -> 0.0081431146 | F37: =C37/$C$95 -> 0 | G37: =D37/$D$95 -> 0.0044611545 | H37: =G37+H36 -> 0.91089881
A38: Banda de tusa | C38: 7.3083333 | D38: =SUM(B38:C38) -> 7.3083333 | E38: =B38/$B$95 -> 0 | F38: =C38/$C$95 -> 0.0096896227 | G38: =D38/$D$95 -> 0.0043812234 | H38: =G38+H37 -> 0.91528003
A39: Bomba de transferencia | B39: 7.1166667 | D39: =SUM(B39:C39) -> 7.1166667 | E39: =B39/$B$95 -> 0.0077874802 | F39: =C39/$C$95 -> 0 | G39: =D39/$D$95 -> 0.0042663224 | H39: =G39+H38 -> 0.91954635
A40: Vagoneta | B40: 0.25 | C40: 6.3666667 | D40: =SUM(B40:C40) -> 6.6166667 | E40: =B40/$B$95 -> 0.00027356488 | F40: =C40/$C$95 -> 0.0084411308 | G40: =D40/$D$95 -> 0.0039665808 | H40: =G40+H39 -> 0.92351293
...

Sheet Pareto nov. 2017
A1: Equipo | B1: h parada 2017 | C1: % | D1: Pareto
A2: Transportador de torta | B2: 44.883333 | C2: =+B2/$B$15 -> 0.41045572 | D2: =+C2 -> 0.41045572
A3: Digestor 1 | B3: 24 | C3: =+B3/$B$15 -> 0.21947874 | D3: =+D2+C3 -> 0.62993446
A4: Tablero de control y automatizacion esterilizacion | B4: 14.5 | C4: =+B4/$B$15 -> 0.13260174 | D4: =+D3+C4 -> 0.7625362
A5: Redler principal de fruta fresca | B5: 7.3333333 | C5: =+B5/$B$15 -> 0.067062948 | D5: =+D4+C5 -> 0.82959915
A6: Vagoneta N°2 | B6: 4.0833333 | C6: =+B6/$B$15 -> 0.037341869 | D6: =+D5+C6 -> 0.86694102
A7: Bomba alimentacion de agua a caldera N°1 | B7: 3.5 | C7: =+B7/$B$15 -> 0.032007316 | D7: =+D6+C7 -> 0.89894833
A8: Elevador de fruto | B8: 3.05 | C8: =+B8/$B$15 -> 0.02789209 | D8: =+D7+C8 -> 0.92684042
A9: Transportador sinfín fibras alimentacion a caldera | B9: 1.8333333 | C9: =+B9/$B$15 -> 0.016765737 | D9: =+D8+C9 -> 0.94360616
A10: Redler de fruta esterelizada N°1 | B10: 1.75 | C10: =+B10/$B$15 -> 0.016003658 | D10: =+D9+C10 -> 0.95960982
A11: Redler transversal de fruta esterilizada | B11: 1.75 | C11: =+B11/$B$15 -> 0.016003658 | D11: =+D10+C11 -> 0.97561347
A12: Transportador sinfín fibras bajo ciclones | B12: 1.5833333 | C12: =+B12/$B$15 -> 0.0144795 | D12: =+D11+C12 -> 0.99009297
A13: Vagoneta N°4 | B13: 0.58333333 | C13: =+B13/$B$15 -> 0.0053345527 | D13: =+D12+C13 -> 0.99542753
A14: Ciclon de fibras | B14: 0.5 | C14: =+B14/$B$15 -> 0.0045724737 | D14: =+D13+C14 -> 1
B15: =SUM(B2:B14) -> 109.35

Sheet Pareto Mar.2018
A2: INDICADORES | B2: CPO
E3: Equipo | F3: Horas de parada | G3: H | H3: Porcentaje acumulado
A4: HPNP | B4: 73.63 | E4: Redler principal de fruta fresca | F4: 16.416667 | G4: 16.416667 | H4: =G4/$G$24 -> 0.25904011 | I4: =H4 -> 0.25904011
A5: HL | B5: 637.2 | E5: Transportador sinfín bajo desfrutador | F5: 11.25 | G5: 11.25 | H5: =G5/$G$24 -> 0.17751479 | I5: =I4+H5 -> 0.4365549
A6: HPP | B6: 28.55 | E6: Tamiz lodos | F6: 5.5 | G6: 5.5 | H6: =G6/$G$24 -> 0.08678501 | I6: =I5+H6 -> 0.52333991
E7: Redler de fruta esterelizada N°1 | F7: 4.6666667 | G7: 4.6666667 | H7: =G7/$G$24 -> 0.073635766 | I7: =I6+H7 -> 0.59697567
E8: Transportador sinfín fibras alimentacion a caldera | F8: 4 | G8: 4 | H8: =G8/$G$24 -> 0.063116371 | I8: =I7+H8 -> 0.66009204
B9: =B4/(B5-B6) -> 0.12097264 | E9: Filtros cepillos N°1 | F9: 4 | G9: 4 | H9: =G9/$G$24 -> 0.063116371 | I9: =I8+H9 -> 0.72320842
E10: Digestor 1 | F10: 2.6666667 | G10: 2.6666667 | H10: =G10/$G$24 -> 0.042077581 | I10: =I9+H10 -> 0.765286
E11: Transportador de torta | F11: 2 | G11: 2 | H11: =G11/$G$24 -> 0.031558185 | I11: =I10+H11 -> 0.79684418
E12: Vagoneta N°3 | F12: 1.5 | G12: 1.5 | H12: =G12/$G$24 -> 0.023668639 | I12: =I11+H12 -> 0.82051282
E13: Tanque lodos tamizados | F13: 1.5 | G13: 1.5 | H13: =G13/$G$24 -> 0.023668639 | I13: =I12+H13 -> 0.84418146
E14: Tambor desfrutador | F14: 1.4166667 | G14: 1.4166667 | H14: =G14/$G$24 -> 0.022353715 | I14: =I13+H14 -> 0.86653517
E15: Tablero de control y automatizacion esterilizacion | F15: 1.3333333 | G15: 1.3333333 | H15: =G15/$G$24 -> 0.02103879 | I15: =I14+H15 -> 0.88757396
E16: Bomba aceite terminado | F16: 1.25 | G16: 1.25 | H16: =G16/$G$24 -> 0.019723866 | I16: =I15+H16 -> 0.90729783
E17: Transportador sinfín distribuidor de fruto | F17: 1.1666667 | G17: 1.1666667 | H17: =G17/$G$24 -> 0.018408941 | I17: =I16+H17 -> 0.92570677
E18: Prensa 2 | F18: 1.0833333 | G18: 1.0833333 | H18: =G18/$G$24 -> 0.017094017 | I18: =I17+H18 -> 0.94280079
E19: Redler de fruta esterelizada N°2 | F19: 1 | G19: 1 | H19: =G19/$G$24 -> 0.015779093 | I19: =I18+H19 -> 0.95857988
E20: Transportador sinfín fibras bajo ciclones | F20: 0.83333333 | G20: 0.83333333 | H20: =G20/$G$24 -> 0.013149244 | I20: =I19+H20 -> 0.97172913
E21: Caldera VR 16 | F21: 0.75 | G21: 0.75 | H21: =G21/$G$24 -> 0.01183432 | I21: =I20+H21 -> 0.98356345
... E23: Autoclave N°2 | F23: 0.29166667 | G23: 0.29166667 | H23: =G23/$G$24 -> 0.0046022354 | I23: =I22+H23 -> 1
G24: =SUM(G4:G23) -> 63.375
